Workbook

Sheet Summary Dashboard
A1: Q4 DEALER SCHEME — SUMMARY DASHBOARD
A3: ZONE-WISE SUMMARY
A4: Zone | B4: Total Dealers | C4: Total Earned Points | D4: Total Points Utilized | E4: Points Remaining | F4: % Utilized | G4: Gifts Selected (Dealers)
A5: North | B5: =COUNTIF(Data!G:G,A5) -> 232 | C5: =SUMIF(Data!G:G,A5,Data!I:I) -> 1187110.9 | D5: {=SUMPRODUCT((Data!G$2:G$293=A5)*IF(Data!J$2:J$293="",0,Data!J$2:J$293))} -> 7500 | E5: =C5-D5 -> 1179610.9 | F5: =IF(C5=0,"",D5/C5) -> 0.0063178596 | G5: =COUNTIFS(Data!G:G,A5,Data!J:J,">0") -> 1
A6: Central | B6: =COUNTIF(Data!G:G,A6) -> 43 | C6: =SUMIF(Data!G:G,A6,Data!I:I) -> 200874.15 | D6: {=SUMPRODUCT((Data!G$2:G$293=A6)*IF(Data!J$2:J$293="",0,Data!J$2:J$293))} -> 6006 | E6: =C6-D6 -> 194868.15 | F6: =IF(C6=0,"",D6/C6) -> 0.029899318 | G6: =COUNTIFS(Data!G:G,A6,Data!J:J,">0") -> 1
A7: East | B7: =COUNTIF(Data!G:G,A7) -> 17 | C7: =SUMIF(Data!G:G,A7,Data!I:I) -> 23787.775 | D7: {=SUMPRODUCT((Data!G$2:G$293=A7)*IF(Data!J$2:J$293="",0,Data!J$2:J$293))} -> 0 | E7: =C7-D7 -> 23787.775 | F7: =IF(C7=0,"",D7/C7) -> 0 | G7: =COUNTIFS(Data!G:G,A7,Data!J:J,">0") -> 0
A8: TOTAL | B8: =SUM(B5:B7) -> 292 | C8: =SUM(C5:C7) -> 1411772.8 | D8: =SUM(D5:D7) -> 13506 | E8: =SUM(E5:E7) -> 1398266.8 | F8: =IF(C8=0,"",D8/C8) -> 0.009566695 | G8: =SUM(G5:G7) -> 2
A10: STATE-WISE SUMMARY
A11: State | B11: Total Dealers | C11: Total Earned Points | D11: Total Points Utilized | E11: Points Remaining | F11: % Utilized | G11: Gifts Selected (Dealers)
A12: BIHAR | B12: {=SUMPRODUCT((UPPER(Data!D$2:D$293)=UPPER(A12))*1)} -> 7 | C12: {=SUMPRODUCT((UPPER(Data!D$2:D$293)=UPPER(A12))*Data!I$2:I$293)} -> 7345.5 | D12: {=SUMPRODUCT((UPPER(Data!D$2:D$293)=UPPER(A12))*IF(Data!J$2:J$293="",0,Data!J$2:J$293))} -> 0 | E12: =C12-D12 -> 7345.5 | F12: =IF(C12=0,"",D12/C12) -> 0 | G12: {=SUMPRODUCT((UPPER(Data!D$2:D$293)=UPPER(A12))*(Data!J$2:J$293>0)*1)} -> 7
A13: CHHATTISGARH | B13: {=SUMPRODUCT((UPPER(Data!D$2:D$293)=UPPER(A13))*1)} -> 2 | C13: {=SUMPRODUCT((UPPER(Data!D$2:D$293)=UPPER(A13))*Data!I$2:I$293)} -> 8252.5 | D13: {=SUMPRODUCT((UPPER(Data!D$2:D$293)=UPPER(A13))*IF(Data!J$2:J$293="",0,Data!J$2:J$293))} -> 0 | E13: =C13-D13 -> 8252.5 | F13: =IF(C13=0,"",D13/C13) -> 0 | G13: {=SUMPRODUCT((UPPER(Data!D$2:D$293)=UPPER(A13))*(Data!J$2:J$293>0)*1)} -> 2
A14: DELHI | B14: {=SUMPRODUCT((UPPER(Data!D$2:D$293)=UPPER(A14))*1)} -> 13 | C14: {=SUMPRODUCT((UPPER(Data!D$2:D$293)=UPPER(A14))*Data!I$2:I$293)} -> 82622.925 | D14: {=SUMPRODUCT((UPPER(Data!D$2:D$293)=UPPER(A14))*IF(Data!J$2:J$293="",0,Data!J$2:J$293))} -> 0 | E14: =C14-D14 -> 82622.925 | F14: =IF(C14=0,"",D14/C14) -> 0 | G14: {=SUMPRODUCT((UPPER(Data!D$2:D$293)=UPPER(A14))*(Data!J$2:J$293>0)*1)} -> 13
A15: HARYANA | B15: {=SUMPRODUCT((UPPER(Data!D$2:D$293)=UPPER(A15))*1)} -> 63 | C15: {=SUMPRODUCT((UPPER(Data!D$2:D$293)=UPPER(A15))*Data!I$2:I$293)} -> 462266.4 | D15: {=SUMPRODUCT((UPPER(Data!D$2:D$293)=UPPER(A15))*IF(Data!J$2:J$293="",0,Data!J$2:J$293))} -> 0 | E15: =C15-D15 -> 462266.4 | F15: =IF(C15=0,"",D15/C15) -> 0 | G15: {=SUMPRODUCT((UPPER(Data!D$2:D$293)=UPPER(A15))*(Data!J$2:J$293>0)*1)} -> 63
A16: HIMACHAL PRADESH | B16: {=SUMPRODUCT((UPPER(Data!D$2:D$293)=UPPER(A16))*1)} -> 1 | C16: {=SUMPRODUCT((UPPER(Data!D$2:D$293)=UPPER(A16))*Data!I$2:I$293)} -> 20956.125 | D16: {=SUMPRODUCT((UPPER(Data!D$2:D$293)=UPPER(A16))*IF(Data!J$2:J$293="",0,Data!J$2:J$293))} -> 0 | E16: =C16-D16 -> 20956.125 | F16: =IF(C16=0,"",D16/C16) -> 0 | G16: {=SUMPRODUCT((UPPER(Data!D$2:D$293)=UPPER(A16))*(Data!J$2:J$293>0)*1)} -> 1
A17: JAMMU AND KASHMIR | B17: {=SUMPRODUCT((UPPER(Data!D$2:D$293)=UPPER(A17))*1)} -> 2 | C17: {=SUMPRODUCT((UPPER(Data!D$2:D$293)=UPPER(A17))*Data!I$2:I$293)} -> 5642.225 | D17: {=SUMPRODUCT((UPPER(Data!D$2:D$293)=UPPER(A17))*IF(Data!J$2:J$293="",0,Data!J$2:J$293))} -> 0 | E17: =C17-D17 -> 5642.225 | F17: =IF(C17=0,"",D17/C17) -> 0 | G17: {=SUMPRODUCT((UPPER(Data!D$2:D$293)=UPPER(A17))*(Data!J$2:J$293>0)*1)} -> 2
A18: JHARKHAND | B18: {=SUMPRODUCT((UPPER(Data!D$2:D$293)=UPPER(A18))*1)} -> 3 | C18: {=SUMPRODUCT((UPPER(Data!D$2:D$293)=UPPER(A18))*Data!I$2:I$293)} -> 2417.75 | D18: {=SUMPRODUCT((UPPER(Data!D$2:D$293)=UPPER(A18))*IF(Data!J$2:J$293="",0,Data!J$2:J$293))} -> 0 | E18: =C18-D18 -> 2417.75 | F18: =IF(C18=0,"",D18/C18) -> 0 | G18: {=SUMPRODUCT((UPPER(Data!D$2:D$293)=UPPER(A18))*(Data!J$2:J$293>0)*1)} -> 3
A19: MADHYA PRADESH | B19: {=SUMPRODUCT((UPPER(Data!D$2:D$293)=UPPER(A19))*1)} -> 36 | C19: {=SUMPRODUCT((UPPER(Data!D$2:D$293)=UPPER(A19))*Data!I$2:I$293)} -> 164860.27 | D19: {=SUMPRODUCT((UPPER(Data!D$2:D$293)=UPPER(A19))*IF(Data!J$2:J$293="",0,Data!J$2:J$293))} -> 6006 | E19: =C19-D19 -> 158854.27 | F19: =IF(C19=0,"",D19/C19) -> 0.03643085 | G19: {=SUMPRODUCT((UPPER(Data!D$2:D$293)=UPPER(A19))*(Data!J$2:J$293>0)*1)} -> 36
A20: MAHARASHTRA | B20: {=SUMPRODUCT((UPPER(Data!D$2:D$293)=UPPER(A20))*1)} -> 4 | C20: {=SUMPRODUCT((UPPER(Data!D$2:D$293)=UPPER(A20))*Data!I$2:I$293)} -> 6543.65 | D20: {=SUMPRODUCT((UPPER(Data!D$2:D$293)=UPPER(A20))*IF(Data!J$2:J$293="",0,Data!J$2:J$293))} -> 0 | E20: =C20-D20 -> 6543.65 | F20: =IF(C20=0,"",D20/C20) -> 0 | G20: {=SUMPRODUCT((UPPER(Data!D$2:D$293)=UPPER(A20))*(Data!J$2:J$293>0)*1)} -> 4
A21: ODISHA | B21: {=SUMPRODUCT((UPPER(Data!D$2:D$293)=UPPER(A21))*1)} -> 11 | C21: {=SUMPRODUCT((UPPER(Data!D$2:D$293)=UPPER(A21))*Data!I$2:I$293)} -> 43417.225 | D21: {=SUMPRODUCT((UPPER(Data!D$2:D$293)=UPPER(A21))*IF(Data!J$2:J$293="",0,Data!J$2:J$293))} -> 0 | E21: =C21-D21 -> 43417.225 | F21: =IF(C21=0,"",D21/C21) -> 0 | G21: {=SUMPRODUCT((UPPER(Data!D$2:D$293)=UPPER(A21))*(Data!J$2:J$293>0)*1)} -> 11
A22: PUNJAB | B22: {=SUMPRODUCT((UPPER(Data!D$2:D$293)=UPPER(A22))*1)} -> 14 | C22: {=SUMPRODUCT((UPPER(Data!D$2:D$293)=UPPER(A22))*Data!I$2:I$293)} -> 56377.675 | D22: {=SUMPRODUCT((UPPER(Data!D$2:D$293)=UPPER(A22))*IF(Data!J$2:J$293="",0,Data!J$2:J$293))} -> 0 | E22: =C22-D22 -> 56377.675 | F22: =IF(C22=0,"",D22/C22) -> 0 | G22: {=SUMPRODUCT((UPPER(Data!D$2:D$293)=UPPER(A22))*(Data!J$2:J$293>0)*1)} -> 14
A23: RAJASTHAN | B23: {=SUMPRODUCT((UPPER(Data!D$2:D$293)=UPPER(A23))*1)} -> 46 | C23: {=SUMPRODUCT((UPPER(Data!D$2:D$293)=UPPER(A23))*Data!I$2:I$293)} -> 215623.9 | D23: {=SUMPRODUCT((UPPER(Data!D$2:D$293)=UPPER(A23))*IF(Data!J$2:J$293="",0,Data!J$2:J$293))} -> 0 | E23: =C23-D23 -> 215623.9 | F23: =IF(C23=0,"",D23/C23) -> 0 | G23: {=SUMPRODUCT((UPPER(Data!D$2:D$293)=UPPER(A23))*(Data!J$2:J$293>0)*1)} -> 46
... A26: WEST BENGAL | B26: {=SUMPRODUCT((UPPER(Data!D$2:D$293)=UPPER(A26))*1)} -> 6 | C26: {=SUMPRODUCT((UPPER(Data!D$2:D$293)=UPPER(A26))*Data!I$2:I$293)} -> 12649.525 | D26: {=SUMPRODUCT((UPPER(Data!D$2:D$293)=UPPER(A26))*IF(Data!J$2:J$293="",0,Data!J$2:J$293))} -> 0 | E26: =C26-D26 -> 12649.525 | F26: =IF(C26=0,"",D26/C26) -> 0 | G26: {=SUMPRODUCT((UPPER(Data!D$2:D$293)=UPPER(A26))*(Data!J$2:J$293>0)*1)} -> 6
A27: TOTAL | B27: =SUM(B12:B26) -> 288 | C27: =SUM(C12:C26) -> 1403794.4 | D27: =SUM(D12:D26) -> 13506 | E27: =SUM(E12:E26) -> 1390288.4 | F27: =IF(C27=0,"",D27/C27) -> 0.0096210668 | G27: =SUM(G12:G26) -> 288
A29: DISTRIBUTOR-WISE SUMMARY
A30: Distributor | B30: Total Dealers | C30: Total Earned Points | D30: Total Points Utilized | E30: Points Remaining | F30: % Utilized | G30: Gifts Selected (Dealers)
A31: AGGARWAL TRADERS | B31: =COUNTIF(Data!C:C,A31) -> 2 | C31: =SUMIF(Data!C:C,A31,Data!I:I) -> 5642.225 | D31: {=SUMPRODUCT((Data!C$2:C$293=A31)*IF(Data!J$2:J$293="",0,Data!J$2:J$293))} -> 0 | E31: =C31-D31 -> 5642.225 | F31: =IF(C31=0,"",D31/C31) -> 0 | G31: =COUNTIFS(Data!C:C,A31,Data!J:J,">0") -> 0
A32: CHANDRA TRADERS | B32: =COUNTIF(Data!C:C,A32) -> 1 | C32: =SUMIF(Data!C:C,A32,Data!I:I) -> 875 | D32: {=SUMPRODUCT((Data!C$2:C$293=A32)*IF(Data!J$2:J$293="",0,Data!J$2:J$293))} -> 0 | E32: =C32-D32 -> 875 | F32: =IF(C32=0,"",D32/C32) -> 0 | G32: =COUNTIFS(Data!C:C,A32,Data!J:J,">0") -> 0
A33: DINESH STEEL PRIVATE LIMITED | B33: =COUNTIF(Data!C:C,A33) -> 12 | C33: =SUMIF(Data!C:C,A33,Data!I:I) -> 35413.625 | D33: {=SUMPRODUCT((Data!C$2:C$293=A33)*IF(Data!J$2:J$293="",0,Data!J$2:J$293))} -> 0 | E33: =C33-D33 -> 35413.625 | F33: =IF(C33=0,"",D33/C33) -> 0 | G33: =COUNTIFS(Data!C:C,A33,Data!J:J,">0") -> 0
A34: GOBINDGARH IRON LLP | B34: =COUNTIF(Data!C:C,A34) -> 12 | C34: =SUMIF(Data!C:C,A34,Data!I:I) -> 24802.75 | D34: {=SUMPRODUCT((Data!C$2:C$293=A34)*IF(Data!J$2:J$293="",0,Data!J$2:J$293))} -> 0 | E34: =C34-D34 -> 24802.75 | F34: =IF(C34=0,"",D34/C34) -> 0 | G34: =COUNTIFS(Data!C:C,A34,Data!J:J,">0") -> 0
A35: GOLDWIN ISPAT PRIVATE LIMITED | B35: =COUNTIF(Data!C:C,A35) -> 2 | C35: =SUMIF(Data!C:C,A35,Data!I:I) -> 3791.15 | D35: {=SUMPRODUCT((Data!C$2:C$293=A35)*IF(Data!J$2:J$293="",0,Data!J$2:J$293))} -> 0 | E35: =C35-D35 -> 3791.15 | F35: =IF(C35=0,"",D35/C35) -> 0 | G35: =COUNTIFS(Data!C:C,A35,Data!J:J,">0") -> 0
A36: Global Steel | B36: =COUNTIF(Data!C:C,A36) -> 9 | C36: =SUMIF(Data!C:C,A36,Data!I:I) -> 41711.775 | D36: {=SUMPRODUCT((Data!C$2:C$293=A36)*IF(Data!J$2:J$293="",0,Data!J$2:J$293))} -> 6006 | E36: =C36-D36 -> 35705.775 | F36: =IF(C36=0,"",D36/C36) -> 0.14398812 | G36: =COUNTIFS(Data!C:C,A36,Data!J:J,">0") -> 1
A37: J P Alloys | B37: =COUNTIF(Data!C:C,A37) -> 20 | C37: =SUMIF(Data!C:C,A37,Data!I:I) -> 126541.6 | D37: {=SUMPRODUCT((Data!C$2:C$293=A37)*IF(Data!J$2:J$293="",0,Data!J$2:J$293))} -> 0 | E37: =C37-D37 -> 126541.6 | F37: =IF(C37=0,"",D37/C37) -> 0 | G37: =COUNTIFS(Data!C:C,A37,Data!J:J,">0") -> 0
A38: JAI DURGA STEELS | B38: =COUNTIF(Data!C:C,A38) -> 21 | C38: =SUMIF(Data!C:C,A38,Data!I:I) -> 166932.73 | D38: {=SUMPRODUCT((Data!C$2:C$293=A38)*IF(Data!J$2:J$293="",0,Data!J$2:J$293))} -> 0 | E38: =C38-D38 -> 166932.73 | F38: =IF(C38=0,"",D38/C38) -> 0 | G38: =COUNTIFS(Data!C:C,A38,Data!J:J,">0") -> 0
A39: KEDIA PIPES PRIVATE LMITED | B39: =COUNTIF(Data!C:C,A39) -> 1 | C39: =SUMIF(Data!C:C,A39,Data!I:I) -> 1593.35 | D39: {=SUMPRODUCT((Data!C$2:C$293=A39)*IF(Data!J$2:J$293="",0,Data!J$2:J$293))} -> 0 | E39: =C39-D39 -> 1593.35 | F39: =IF(C39=0,"",D39/C39) -> 0 | G39: =COUNTIFS(Data!C:C,A39,Data!J:J,">0") -> 0
A40: KHARAKIA METALS PRIVATE LIMITED | B40: =COUNTIF(Data!C:C,A40) -> 7 | C40: =SUMIF(Data!C:C,A40,Data!I:I) -> 7943.5 | D40: {=SUMPRODUCT((Data!C$2:C$293=A40)*IF(Data!J$2:J$293="",0,Data!J$2:J$293))} -> 0 | E40: =C40-D40 -> 7943.5 | F40: =IF(C40=0,"",D40/C40) -> 0 | G40: =COUNTIFS(Data!C:C,A40,Data!J:J,">0") -> 0
A41: Khandelwal Associates | B41: =COUNTIF(Data!C:C,A41) -> 7 | C41: =SUMIF(Data!C:C,A41,Data!I:I) -> 61452.375 | D41: {=SUMPRODUCT((Data!C$2:C$293=A41)*IF(Data!J$2:J$293="",0,Data!J$2:J$293))} -> 0 | E41: =C41-D41 -> 61452.375 | F41: =IF(C41=0,"",D41/C41) -> 0 | G41: =COUNTIFS(Data!C:C,A41,Data!J:J,">0") -> 0
A42: M R ASSOCIATES | B42: =COUNTIF(Data!C:C,A42) -> 15 | C42: =SUMIF(Data!C:C,A42,Data!I:I) -> 59395.9 | D42: {=SUMPRODUCT((Data!C$2:C$293=A42)*IF(Data!J$2:J$293="",0,Data!J$2:J$293))} -> 0 | E42: =C42-D42 -> 59395.9 | F42: =IF(C42=0,"",D42/C42) -> 0 | G42: =COUNTIFS(Data!C:C,A42,Data!J:J,">0") -> 0
... A64: TIRUPATI SALES | B64: =COUNTIF(Data!C:C,A64) -> 1 | C64: =SUMIF(Data!C:C,A64,Data!I:I) -> 826.5 | D64: {=SUMPRODUCT((Data!C$2:C$293=A64)*IF(Data!J$2:J$293="",0,Data!J$2:J$293))} -> 0 | E64: =C64-D64 -> 826.5 | F64: =IF(C64=0,"",D64/C64) -> 0 | G64: =COUNTIFS(Data!C:C,A64,Data!J:J,">0") -> 0
A65: TOTAL | B65: =SUM(B31:B64) -> 292 | C65: =SUM(C31:C64) -> 1411772.8 | D65: =SUM(D31:D64) -> 13506 | E65: =SUM(E31:E64) -> 1398266.8 | F65: =IF(C65=0,"",D65/C65) -> 0.009566695 | G65: =SUM(G31:G64) -> 2
A67: GIFT SLAB DISTRIBUTION
...

Sheet Data
A1: SF Id | B1: Retailer Name | C1: Distributor Name | D1: State Name | E1: District Name | F1: Distributor self-counter (Yes/No) | G1: Zone | H1: Q4 Vol. under eligible scheme | I1: Earned Points | J1: Point utilized | K1: Point Balance | L1: Current gift | M1: Gift 1 | N1: Gift 2 | O1: Gift 3 | P1: Gift 4 | Q1: Gift 5 | R1: Gift 6 | S1: Gift 7 [Amazon Voucher] | T1: Gift 1 Points | U1: Gift 2 Points | V1: Gift 3 Points | W1: Gift 4 Points | X1: Gift 5 Points | Y1: Gift 6 Points | Z1: Gift 7 Points | AA1: Eligible Slab | AB1: Max Eligible Gift
A2: 001fw00000MQoULAA1 | B2: ANURAG SALES | C2: Global Steel | D2: CHHATTISGARH | E2: RAIPUR | F2: No | G2: Central | H2: 200 | I2: 7500 | J2: =IF(SUM(T2:Z2)=0,"",SUM(T2:Z2)) | K2: =IF(J2="","",I2-J2) | L2: Samsung front-load washing machine | T2: =IF(M2="",0,INDEX(Sheet2!A$2:A$6,MATCH(M2,Sheet2!C$2:C$6,0))) -> 0 | U2: =IF(N2="",0,INDEX(Sheet2!A$2:A$6,MATCH(N2,Sheet2!C$2:C$6,0))) -> 0 | V2: =IF(O2="",0,INDEX(Sheet2!A$2:A$6,MATCH(O2,Sheet2!C$2:C$6,0))) -> 0 | W2: =IF(P2="",0,INDEX(Sheet2!A$2:A$6,MATCH(P2,Sheet2!C$2:C$6,0))) -> 0 | X2: =IF(Q2="",0,INDEX(Sheet2!A$2:A$6,MATCH(Q2,Sheet2!C$2:C$6,0))) -> 0 | Y2: =IF(R2="",0,INDEX(Sheet2!A$2:A$6,MATCH(R2,Sheet2!C$2:C$6,0))) -> 0 | Z2: =IF(S2="Yes",I2-SUM(T2:Y2),0) -> 0 | AA2: =IF(I2>=7500,"E",IF(I2>=6800,"D",IF(I2>=4200,"C",IF(I2>=3000,"B",IF(I2>=750,"A","Below Slab"))))) -> E | AB2: =IF(I2>=7500,"Samsung front-load washing machine",IF(I2>=6800,"Apple iPad",IF(I2>=4200,"Robot Vacuum cleaner",IF(I2>=3000,"Sony - sound bar, woofer and speakers",IF(I2>=750,"Foot massager","Not eligible"))))) -> Samsung front-load washing machine
A3: 001fw000007ARJ6AAO | B3: BOLD STEEL SUPPLIERS | C3: R. K. ENTERPRISES | D3: CHHATTISGARH | E3: RAIPUR | F3: No | G3: Central | H3: 30.1 | I3: 752.5 | J3: =IF(SUM(T3:Z3)=0,"",SUM(T3:Z3)) | K3: =IF(J3="","",I3-J3) | L3: Foot massager | T3: =IF(M3="",0,INDEX(Sheet2!A$2:A$6,MATCH(M3,Sheet2!C$2:C$6,0))) -> 0 | U3: =IF(N3="",0,INDEX(Sheet2!A$2:A$6,MATCH(N3,Sheet2!C$2:C$6,0))) -> 0 | V3: =IF(O3="",0,INDEX(Sheet2!A$2:A$6,MATCH(O3,Sheet2!C$2:C$6,0))) -> 0 | W3: =IF(P3="",0,INDEX(Sheet2!A$2:A$6,MATCH(P3,Sheet2!C$2:C$6,0))) -> 0 | X3: =IF(Q3="",0,INDEX(Sheet2!A$2:A$6,MATCH(Q3,Sheet2!C$2:C$6,0))) -> 0 | Y3: =IF(R3="",0,INDEX(Sheet2!A$2:A$6,MATCH(R3,Sheet2!C$2:C$6,0))) -> 0 | Z3: =IF(S3="Yes",I3-SUM(T3:Y3),0) -> 0 | AA3: =IF(I3>=7500,"E",IF(I3>=6800,"D",IF(I3>=4200,"C",IF(I3>=3000,"B",IF(I3>=750,"A","Below Slab"))))) -> A | AB3: =IF(I3>=7500,"Samsung front-load washing machine",IF(I3>=6800,"Apple iPad",IF(I3>=4200,"Robot Vacuum cleaner",IF(I3>=3000,"Sony - sound bar, woofer and speakers",IF(I3>=750,"Foot massager","Not eligible"))))) -> Foot massager
A4: 001J1000009H3hzIAC | B4: ATC9 STEELS LIMITED | C4: Global Steel | D4: MADHYA PRADESH | E4: BHOPAL | F4: No | G4: Central | H4: 207.52 | I4: 7782 | J4: =IF(SUM(T4:Z4)=0,"",SUM(T4:Z4)) | K4: =IF(J4="","",I4-J4) | L4: Samsung front-load washing machine | T4: =IF(M4="",0,INDEX(Sheet2!A$2:A$6,MATCH(M4,Sheet2!C$2:C$6,0))) -> 0 | U4: =IF(N4="",0,INDEX(Sheet2!A$2:A$6,MATCH(N4,Sheet2!C$2:C$6,0))) -> 0 | V4: =IF(O4="",0,INDEX(Sheet2!A$2:A$6,MATCH(O4,Sheet2!C$2:C$6,0))) -> 0 | W4: =IF(P4="",0,INDEX(Sheet2!A$2:A$6,MATCH(P4,Sheet2!C$2:C$6,0))) -> 0 | X4: =IF(Q4="",0,INDEX(Sheet2!A$2:A$6,MATCH(Q4,Sheet2!C$2:C$6,0))) -> 0 | Y4: =IF(R4="",0,INDEX(Sheet2!A$2:A$6,MATCH(R4,Sheet2!C$2:C$6,0))) -> 0 | Z4: =IF(S4="Yes",I4-SUM(T4:Y4),0) -> 0 | AA4: =IF(I4>=7500,"E",IF(I4>=6800,"D",IF(I4>=4200,"C",IF(I4>=3000,"B",IF(I4>=750,"A","Below Slab"))))) -> E | AB4: =IF(I4>=7500,"Samsung front-load washing machine",IF(I4>=6800,"Apple iPad",IF(I4>=4200,"Robot Vacuum cleaner",IF(I4>=3000,"Sony - sound bar, woofer and speakers",IF(I4>=750,"Foot massager","Not eligible"))))) -> Samsung front-load washing machine
A5: 001J100000RypIXIAZ | B5: CHAYNIKA ASSOCIATES | C5: Global Steel | D5: MADHYA PRADESH | E5: Niwari | F5: No | G5: Central | H5: 274.52 | I5: 10294.5 | J5: =IF(SUM(T5:Z5)=0,"",SUM(T5:Z5)) | K5: =IF(J5="","",I5-J5) | L5: Samsung front-load washing machine | T5: =IF(M5="",0,INDEX(Sheet2!A$2:A$6,MATCH(M5,Sheet2!C$2:C$6,0))) -> 0 | U5: =IF(N5="",0,INDEX(Sheet2!A$2:A$6,MATCH(N5,Sheet2!C$2:C$6,0))) -> 0 | V5: =IF(O5="",0,INDEX(Sheet2!A$2:A$6,MATCH(O5,Sheet2!C$2:C$6,0))) -> 0 | W5: =IF(P5="",0,INDEX(Sheet2!A$2:A$6,MATCH(P5,Sheet2!C$2:C$6,0))) -> 0 | X5: =IF(Q5="",0,INDEX(Sheet2!A$2:A$6,MATCH(Q5,Sheet2!C$2:C$6,0))) -> 0 | Y5: =IF(R5="",0,INDEX(Sheet2!A$2:A$6,MATCH(R5,Sheet2!C$2:C$6,0))) -> 0 | Z5: =IF(S5="Yes",I5-SUM(T5:Y5),0) -> 0 | AA5: =IF(I5>=7500,"E",IF(I5>=6800,"D",IF(I5>=4200,"C",IF(I5>=3000,"B",IF(I5>=750,"A","Below Slab"))))) -> E | AB5: =IF(I5>=7500,"Samsung front-load washing machine",IF(I5>=6800,"Apple iPad",IF(I5>=4200,"Robot Vacuum cleaner",IF(I5>=3000,"Sony - sound bar, woofer and speakers",IF(I5>=750,"Foot massager","Not eligible"))))) -> Samsung front-load washing machine
A6: 0015g000015zvW3AAI | B6: SANJAY STEEL TRADERS | C6: Global Steel | D6: MADHYA PRADESH | E6: REWA | F6: No | G6: Central | H6: 93.59 | I6: 2573.725 | J6: =IF(SUM(T6:Z6)=0,"",SUM(T6:Z6)) | K6: =IF(J6="","",I6-J6) | L6: Foot massager | T6: =IF(M6="",0,INDEX(Sheet2!A$2:A$6,MATCH(M6,Sheet2!C$2:C$6,0))) -> 0 | U6: =IF(N6="",0,INDEX(Sheet2!A$2:A$6,MATCH(N6,Sheet2!C$2:C$6,0))) -> 0 | V6: =IF(O6="",0,INDEX(Sheet2!A$2:A$6,MATCH(O6,Sheet2!C$2:C$6,0))) -> 0 | W6: =IF(P6="",0,INDEX(Sheet2!A$2:A$6,MATCH(P6,Sheet2!C$2:C$6,0))) -> 0 | X6: =IF(Q6="",0,INDEX(Sheet2!A$2:A$6,MATCH(Q6,Sheet2!C$2:C$6,0))) -> 0 | Y6: =IF(R6="",0,INDEX(Sheet2!A$2:A$6,MATCH(R6,Sheet2!C$2:C$6,0))) -> 0 | Z6: =IF(S6="Yes",I6-SUM(T6:Y6),0) -> 0 | AA6: =IF(I6>=7500,"E",IF(I6>=6800,"D",IF(I6>=4200,"C",IF(I6>=3000,"B",IF(I6>=750,"A","Below Slab"))))) -> A | AB6: =IF(I6>=7500,"Samsung front-load washing machine",IF(I6>=6800,"Apple iPad",IF(I6>=4200,"Robot Vacuum cleaner",IF(I6>=3000,"Sony - sound bar, woofer and speakers",IF(I6>=750,"Foot massager","Not eligible"))))) -> Foot massager
A7: 001fw00000IwnR1AAJ | B7: ANAND STEEL | C7: Global Steel | D7: MADHYA PRADESH | E7: SAGAR | F7: No | G7: Central | H7: 80.58 | I7: 2215.95 | J7: =IF(SUM(T7:Z7)=0,"",SUM(T7:Z7)) | K7: =IF(J7="","",I7-J7) | L7: Foot massager | T7: =IF(M7="",0,INDEX(Sheet2!A$2:A$6,MATCH(M7,Sheet2!C$2:C$6,0))) -> 0 | U7: =IF(N7="",0,INDEX(Sheet2!A$2:A$6,MATCH(N7,Sheet2!C$2:C$6,0))) -> 0 | V7: =IF(O7="",0,INDEX(Sheet2!A$2:A$6,MATCH(O7,Sheet2!C$2:C$6,0))) -> 0 | W7: =IF(P7="",0,INDEX(Sheet2!A$2:A$6,MATCH(P7,Sheet2!C$2:C$6,0))) -> 0 | X7: =IF(Q7="",0,INDEX(Sheet2!A$2:A$6,MATCH(Q7,Sheet2!C$2:C$6,0))) -> 0 | Y7: =IF(R7="",0,INDEX(Sheet2!A$2:A$6,MATCH(R7,Sheet2!C$2:C$6,0))) -> 0 | Z7: =IF(S7="Yes",I7-SUM(T7:Y7),0) -> 0 | AA7: =IF(I7>=7500,"E",IF(I7>=6800,"D",IF(I7>=4200,"C",IF(I7>=3000,"B",IF(I7>=750,"A","Below Slab"))))) -> A | AB7: =IF(I7>=7500,"Samsung front-load washing machine",IF(I7>=6800,"Apple iPad",IF(I7>=4200,"Robot Vacuum cleaner",IF(I7>=3000,"Sony - sound bar, woofer and speakers",IF(I7>=750,"Foot massager","Not eligible"))))) -> Foot massager
A8: 001J100000TuwCtIAJ | B8: GUNJAN ENTERPRISES | C8: Global Steel | D8: MADHYA PRADESH | E8: BHOPAL | F8: No | G8: Central | H8: 43.35 | I8: 1083.75 | J8: =IF(SUM(T8:Z8)=0,"",SUM(T8:Z8)) | K8: =IF(J8="","",I8-J8) | L8: Foot massager | T8: =IF(M8="",0,INDEX(Sheet2!A$2:A$6,MATCH(M8,Sheet2!C$2:C$6,0))) -> 0 | U8: =IF(N8="",0,INDEX(Sheet2!A$2:A$6,MATCH(N8,Sheet2!C$2:C$6,0))) -> 0 | V8: =IF(O8="",0,INDEX(Sheet2!A$2:A$6,MATCH(O8,Sheet2!C$2:C$6,0))) -> 0 | W8: =IF(P8="",0,INDEX(Sheet2!A$2:A$6,MATCH(P8,Sheet2!C$2:C$6,0))) -> 0 | X8: =IF(Q8="",0,INDEX(Sheet2!A$2:A$6,MATCH(Q8,Sheet2!C$2:C$6,0))) -> 0 | Y8: =IF(R8="",0,INDEX(Sheet2!A$2:A$6,MATCH(R8,Sheet2!C$2:C$6,0))) -> 0 | Z8: =IF(S8="Yes",I8-SUM(T8:Y8),0) -> 0 | AA8: =IF(I8>=7500,"E",IF(I8>=6800,"D",IF(I8>=4200,"C",IF(I8>=3000,"B",IF(I8>=750,"A","Below Slab"))))) -> A | AB8: =IF(I8>=7500,"Samsung front-load washing machine",IF(I8>=6800,"Apple iPad",IF(I8>=4200,"Robot Vacuum cleaner",IF(I8>=3000,"Sony - sound bar, woofer and speakers",IF(I8>=750,"Foot massager","Not eligible"))))) -> Foot massager
A9: 001fw000004MziWAAS | B9: DISHA TRADERS | C9: Global Steel | D9: MADHYA PRADESH | E9: BHOPAL | F9: No | G9: Central | H9: 113.07 | I9: 3392.1 | J9: =IF(SUM(T9:Z9)=0,"",SUM(T9:Z9)) | K9: =IF(J9="","",I9-J9) | L9: Sony - Sound bar, woofer and speakers | T9: =IF(M9="",0,INDEX(Sheet2!A$2:A$6,MATCH(M9,Sheet2!C$2:C$6,0))) -> 0 | U9: =IF(N9="",0,INDEX(Sheet2!A$2:A$6,MATCH(N9,Sheet2!C$2:C$6,0))) -> 0 | V9: =IF(O9="",0,INDEX(Sheet2!A$2:A$6,MATCH(O9,Sheet2!C$2:C$6,0))) -> 0 | W9: =IF(P9="",0,INDEX(Sheet2!A$2:A$6,MATCH(P9,Sheet2!C$2:C$6,0))) -> 0 | X9: =IF(Q9="",0,INDEX(Sheet2!A$2:A$6,MATCH(Q9,Sheet2!C$2:C$6,0))) -> 0 | Y9: =IF(R9="",0,INDEX(Sheet2!A$2:A$6,MATCH(R9,Sheet2!C$2:C$6,0))) -> 0 | Z9: =IF(S9="Yes",I9-SUM(T9:Y9),0) -> 0 | AA9: =IF(I9>=7500,"E",IF(I9>=6800,"D",IF(I9>=4200,"C",IF(I9>=3000,"B",IF(I9>=750,"A","Below Slab"))))) -> B | AB9: =IF(I9>=7500,"Samsung front-load washing machine",IF(I9>=6800,"Apple iPad",IF(I9>=4200,"Robot Vacuum cleaner",IF(I9>=3000,"Sony - sound bar, woofer and speakers",IF(I9>=750,"Foot massager","Not eligible"))))) -> Sony - sound bar, woofer and speakers
A10: 001J100000RypIrIAJ | B10: SHEROCK VENTURES PRIVATE LIMITED | C10: Global Steel | D10: MADHYA PRADESH | E10: BHOPAL | F10: No | G10: Central | H10: 184.8 | I10: 6006 | J10: =IF(SUM(T10:Z10)=0,"",SUM(T10:Z10)) -> 6006 | K10: =IF(J10="","",I10-J10) -> 0 | L10: Robot Vacuum cleaner | S10: Yes | T10: =IF(M10="",0,INDEX(Sheet2!A$2:A$6,MATCH(M10,Sheet2!C$2:C$6,0))) -> 0 | U10: =IF(N10="",0,INDEX(Sheet2!A$2:A$6,MATCH(N10,Sheet2!C$2:C$6,0))) -> 0 | V10: =IF(O10="",0,INDEX(Sheet2!A$2:A$6,MATCH(O10,Sheet2!C$2:C$6,0))) -> 0 | W10: =IF(P10="",0,INDEX(Sheet2!A$2:A$6,MATCH(P10,Sheet2!C$2:C$6,0))) -> 0 | X10: =IF(Q10="",0,INDEX(Sheet2!A$2:A$6,MATCH(Q10,Sheet2!C$2:C$6,0))) -> 0 | Y10: =IF(R10="",0,INDEX(Sheet2!A$2:A$6,MATCH(R10,Sheet2!C$2:C$6,0))) -> 0 | Z10: =IF(S10="Yes",I10-SUM(T10:Y10),0) -> 6006 | AA10: =IF(I10>=7500,"E",IF(I10>=6800,"D",IF(I10>=4200,"C",IF(I10>=3000,"B",IF(I10>=750,"A","Below Slab"))))) -> C | AB10: =IF(I10>=7500,"Samsung front-load washing machine",IF(I10>=6800,"Apple iPad",IF(I10>=4200,"Robot Vacuum cleaner",IF(I10>=3000,"Sony - sound bar, woofer and speakers",IF(I10>=750,"Foot massager","Not eligible"))))) -> Robot Vacuum cleaner
A11: 0015g00001XK3RqAAL | B11: LAXMI ISPAT COMPANY | C11: Global Steel | D11: MADHYA PRADESH | E11: JABALPUR | F11: No | G11: Central | H11: 34.55 | I11: 863.75 | J11: =IF(SUM(T11:Z11)=0,"",SUM(T11:Z11)) | K11: =IF(J11="","",I11-J11) | L11: Foot massager | T11: =IF(M11="",0,INDEX(Sheet2!A$2:A$6,MATCH(M11,Sheet2!C$2:C$6,0))) -> 0 | U11: =IF(N11="",0,INDEX(Sheet2!A$2:A$6,MATCH(N11,Sheet2!C$2:C$6,0))) -> 0 | V11: =IF(O11="",0,INDEX(Sheet2!A$2:A$6,MATCH(O11,Sheet2!C$2:C$6,0))) -> 0 | W11: =IF(P11="",0,INDEX(Sheet2!A$2:A$6,MATCH(P11,Sheet2!C$2:C$6,0))) -> 0 | X11: =IF(Q11="",0,INDEX(Sheet2!A$2:A$6,MATCH(Q11,Sheet2!C$2:C$6,0))) -> 0 | Y11: =IF(R11="",0,INDEX(Sheet2!A$2:A$6,MATCH(R11,Sheet2!C$2:C$6,0))) -> 0 | Z11: =IF(S11="Yes",I11-SUM(T11:Y11),0) -> 0 | AA11: =IF(I11>=7500,"E",IF(I11>=6800,"D",IF(I11>=4200,"C",IF(I11>=3000,"B",IF(I11>=750,"A","Below Slab"))))) -> A | AB11: =IF(I11>=7500,"Samsung front-load washing machine",IF(I11>=6800,"Apple iPad",IF(I11>=4200,"Robot Vacuum cleaner",IF(I11>=3000,"Sony - sound bar, woofer and speakers",IF(I11>=750,"Foot massager","Not eligible"))))) -> Foot massager
A12: 0015g00001XM8sxAAD | B12: NEW JAIN STEEL | C12: R. K. ENTERPRISES | D12: MADHYA PRADESH | E12: INDORE | F12: No | G12: Central | H12: 223.26 | I12: 8372.25 | J12: =IF(SUM(T12:Z12)=0,"",SUM(T12:Z12)) | K12: =IF(J12="","",I12-J12) | L12: Samsung front-load washing machine | T12: =IF(M12="",0,INDEX(Sheet2!A$2:A$6,MATCH(M12,Sheet2!C$2:C$6,0))) -> 0 | U12: =IF(N12="",0,INDEX(Sheet2!A$2:A$6,MATCH(N12,Sheet2!C$2:C$6,0))) -> 0 | V12: =IF(O12="",0,INDEX(Sheet2!A$2:A$6,MATCH(O12,Sheet2!C$2:C$6,0))) -> 0 | W12: =IF(P12="",0,INDEX(Sheet2!A$2:A$6,MATCH(P12,Sheet2!C$2:C$6,0))) -> 0 | X12: =IF(Q12="",0,INDEX(Sheet2!A$2:A$6,MATCH(Q12,Sheet2!C$2:C$6,0))) -> 0 | Y12: =IF(R12="",0,INDEX(Sheet2!A$2:A$6,MATCH(R12,Sheet2!C$2:C$6,0))) -> 0 | Z12: =IF(S12="Yes",I12-SUM(T12:Y12),0) -> 0 | AA12: =IF(I12>=7500,"E",IF(I12>=6800,"D",IF(I12>=4200,"C",IF(I12>=3000,"B",IF(I12>=750,"A","Below Slab"))))) -> E | AB12: =IF(I12>=7500,"Samsung front-load washing machine",IF(I12>=6800,"Apple iPad",IF(I12>=4200,"Robot Vacuum cleaner",IF(I12>=3000,"Sony - sound bar, woofer and speakers",IF(I12>=750,"Foot massager","Not eligible"))))) -> Samsung front-load washing machine
A13: 001J100000RyrcBIAR | B13: M/S BAHUBALI TRADING COMPANY | C13: R. K. ENTERPRISES | D13: MADHYA PRADESH | E13: INDORE | F13: No | G13: Central | H13: 166.88 | I13: 5423.6 | J13: =IF(SUM(T13:Z13)=0,"",SUM(T13:Z13)) | K13: =IF(J13="","",I13-J13) | L13: Robot Vacuum cleaner | T13: =IF(M13="",0,INDEX(Sheet2!A$2:A$6,MATCH(M13,Sheet2!C$2:C$6,0))) -> 0 | U13: =IF(N13="",0,INDEX(Sheet2!A$2:A$6,MATCH(N13,Sheet2!C$2:C$6,0))) -> 0 | V13: =IF(O13="",0,INDEX(Sheet2!A$2:A$6,MATCH(O13,Sheet2!C$2:C$6,0))) -> 0 | W13: =IF(P13="",0,INDEX(Sheet2!A$2:A$6,MATCH(P13,Sheet2!C$2:C$6,0))) -> 0 | X13: =IF(Q13="",0,INDEX(Sheet2!A$2:A$6,MATCH(Q13,Sheet2!C$2:C$6,0))) -> 0 | Y13: =IF(R13="",0,INDEX(Sheet2!A$2:A$6,MATCH(R13,Sheet2!C$2:C$6,0))) -> 0 | Z13: =IF(S13="Yes",I13-SUM(T13:Y13),0) -> 0 | AA13: =IF(I13>=7500,"E",IF(I13>=6800,"D",IF(I13>=4200,"C",IF(I13>=3000,"B",IF(I13>=750,"A","Below Slab"))))) -> C | AB13: =IF(I13>=7500,"Samsung front-load washing machine",IF(I13>=6800,"Apple iPad",IF(I13>=4200,"Robot Vacuum cleaner",IF(I13>=3000,"Sony - sound bar, woofer and speakers",IF(I13>=750,"Foot massager","Not eligible"))))) -> Robot Vacuum cleaner
A14: 001J1000002mer3IAA | B14: SHREE NAKODA STEELS | C14: R. K. ENTERPRISES | D14: MADHYA PRADESH | E14: INDORE | F14: No | G14: Central | H14: 467.67 | I14: 17537.625 | J14: =IF(SUM(T14:Z14)=0,"",SUM(T14:Z14)) | K14: =IF(J14="","",I14-J14) | L14: Samsung front-load washing machine | T14: =IF(M14="",0,INDEX(Sheet2!A$2:A$6,MATCH(M14,Sheet2!C$2:C$6,0))) -> 0 | U14: =IF(N14="",0,INDEX(Sheet2!A$2:A$6,MATCH(N14,Sheet2!C$2:C$6,0))) -> 0 | V14: =IF(O14="",0,INDEX(Sheet2!A$2:A$6,MATCH(O14,Sheet2!C$2:C$6,0))) -> 0 | W14: =IF(P14="",0,INDEX(Sheet2!A$2:A$6,MATCH(P14,Sheet2!C$2:C$6,0))) -> 0 | X14: =IF(Q14="",0,INDEX(Sheet2!A$2:A$6,MATCH(Q14,Sheet2!C$2:C$6,0))) -> 0 | Y14: =IF(R14="",0,INDEX(Sheet2!A$2:A$6,MATCH(R14,Sheet2!C$2:C$6,0))) -> 0 | Z14: =IF(S14="Yes",I14-SUM(T14:Y14),0) -> 0 | AA14: =IF(I14>=7500,"E",IF(I14>=6800,"D",IF(I14>=4200,"C",IF(I14>=3000,"B",IF(I14>=750,"A","Below Slab"))))) -> E | AB14: =IF(I14>=7500,"Samsung front-load washing machine",IF(I14>=6800,"Apple iPad",IF(I14>=4200,"Robot Vacuum cleaner",IF(I14>=3000,"Sony - sound bar, woofer and speakers",IF(I14>=750,"Foot massager","Not eligible"))))) -> Samsung front-load washing machine
A15: 001fw000004hGwxAAE | B15: SHARVI ENTERPRISES | C15: R. K. ENTERPRISES | D15: MADHYA PRADESH | E15: DHAR | F15: No | G15: Central | H15: 392.75 | I15: 14728.125 | J15: =IF(SUM(T15:Z15)=0,"",SUM(T15:Z15)) | K15: =IF(J15="","",I15-J15) | L15: Samsung front-load washing machine | T15: =IF(M15="",0,INDEX(Sheet2!A$2:A$6,MATCH(M15,Sheet2!C$2:C$6,0))) -> 0 | U15: =IF(N15="",0,INDEX(Sheet2!A$2:A$6,MATCH(N15,Sheet2!C$2:C$6,0))) -> 0 | V15: =IF(O15="",0,INDEX(Sheet2!A$2:A$6,MATCH(O15,Sheet2!C$2:C$6,0))) -> 0 | W15: =IF(P15="",0,INDEX(Sheet2!A$2:A$6,MATCH(P15,Sheet2!C$2:C$6,0))) -> 0 | X15: =IF(Q15="",0,INDEX(Sheet2!A$2:A$6,MATCH(Q15,Sheet2!C$2:C$6,0))) -> 0 | Y15: =IF(R15="",0,INDEX(Sheet2!A$2:A$6,MATCH(R15,Sheet2!C$2:C$6,0))) -> 0 | Z15: =IF(S15="Yes",I15-SUM(T15:Y15),0) -> 0 | AA15: =IF(I15>=7500,"E",IF(I15>=6800,"D",IF(I15>=4200,"C",IF(I15>=3000,"B",IF(I15>=750,"A","Below Slab"))))) -> E | AB15: =IF(I15>=7500,"Samsung front-load washing machine",IF(I15>=6800,"Apple iPad",IF(I15>=4200,"Robot Vacuum cleaner",IF(I15>=3000,"Sony - sound bar, woofer and speakers",IF(I15>=750,"Foot massager","Not eligible"))))) -> Samsung front-load washing machine
A16: 001J1000006KXIRIA4 | B16: TARMAL ENTERPRISES | C16: R. K. ENTERPRISES | D16: MADHYA PRADESH | E16: MANDSAUR | F16: No | G16: Central | H16: 41.44 | I16: 1036 | J16: =IF(SUM(T16:Z16)=0,"",SUM(T16:Z16)) | K16: =IF(J16="","",I16-J16) | L16: Foot massager | T16: =IF(M16="",0,INDEX(Sheet2!A$2:A$6,MATCH(M16,Sheet2!C$2:C$6,0))) -> 0 | U16: =IF(N16="",0,INDEX(Sheet2!A$2:A$6,MATCH(N16,Sheet2!C$2:C$6,0))) -> 0 | V16: =IF(O16="",0,INDEX(Sheet2!A$2:A$6,MATCH(O16,Sheet2!C$2:C$6,0))) -> 0 | W16: =IF(P16="",0,INDEX(Sheet2!A$2:A$6,MATCH(P16,Sheet2!C$2:C$6,0))) -> 0 | X16: =IF(Q16="",0,INDEX(Sheet2!A$2:A$6,MATCH(Q16,Sheet2!C$2:C$6,0))) -> 0 | Y16: =IF(R16="",0,INDEX(Sheet2!A$2:A$6,MATCH(R16,Sheet2!C$2:C$6,0))) -> 0 | Z16: =IF(S16="Yes",I16-SUM(T16:Y16),0) -> 0 | AA16: =IF(I16>=7500,"E",IF(I16>=6800,"D",IF(I16>=4200,"C",IF(I16>=3000,"B",IF(I16>=750,"A","Below Slab"))))) -> A | AB16: =IF(I16>=7500,"Samsung front-load washing machine",IF(I16>=6800,"Apple iPad",IF(I16>=4200,"Robot Vacuum cleaner",IF(I16>=3000,"Sony - sound bar, woofer and speakers",IF(I16>=750,"Foot massager","Not eligible"))))) -> Foot massager
A17: 001J100000Ge62uIAB | B17: P.D. ENTERPRISES | C17: R. K. ENTERPRISES | D17: MADHYA PRADESH | E17: RAJGARH | F17: No | G17: Central | H17: 41.5 | I17: 1037.5 | J17: =IF(SUM(T17:Z17)=0,"",SUM(T17:Z17)) | K17: =IF(J17="","",I17-J17) | L17: Foot massager | T17: =IF(M17="",0,INDEX(Sheet2!A$2:A$6,MATCH(M17,Sheet2!C$2:C$6,0))) -> 0 | U17: =IF(N17="",0,INDEX(Sheet2!A$2:A$6,MATCH(N17,Sheet2!C$2:C$6,0))) -> 0 | V17: =IF(O17="",0,INDEX(Sheet2!A$2:A$6,MATCH(O17,Sheet2!C$2:C$6,0))) -> 0 | W17: =IF(P17="",0,INDEX(Sheet2!A$2:A$6,MATCH(P17,Sheet2!C$2:C$6,0))) -> 0 | X17: =IF(Q17="",0,INDEX(Sheet2!A$2:A$6,MATCH(Q17,Sheet2!C$2:C$6,0))) -> 0 | Y17: =IF(R17="",0,INDEX(Sheet2!A$2:A$6,MATCH(R17,Sheet2!C$2:C$6,0))) -> 0 | Z17: =IF(S17="Yes",I17-SUM(T17:Y17),0) -> 0 | AA17: =IF(I17>=7500,"E",IF(I17>=6800,"D",IF(I17>=4200,"C",IF(I17>=3000,"B",IF(I17>=750,"A","Below Slab"))))) -> A | AB17: =IF(I17>=7500,"Samsung front-load washing machine",IF(I17>=6800,"Apple iPad",IF(I17>=4200,"Robot Vacuum cleaner",IF(I17>=3000,"Sony - sound bar, woofer and speakers",IF(I17>=750,"Foot massager","Not eligible"))))) -> Foot massager
A18: 001J1000006V8u0IAC | B18: KHANDELWAL AGENCIES PRIVATE LIMITED | C18: R. K. ENTERPRISES | D18: MADHYA PRADESH | E18: INDORE | F18: No | G18: Central | H18: 226 | I18: 8475 | J18: =IF(SUM(T18:Z18)=0,"",SUM(T18:Z18)) | K18: =IF(J18="","",I18-J18) | L18: Samsung front-load washing machine | T18: =IF(M18="",0,INDEX(Sheet2!A$2:A$6,MATCH(M18,Sheet2!C$2:C$6,0))) -> 0 | U18: =IF(N18="",0,INDEX(Sheet2!A$2:A$6,MATCH(N18,Sheet2!C$2:C$6,0))) -> 0 | V18: =IF(O18="",0,INDEX(Sheet2!A$2:A$6,MATCH(O18,Sheet2!C$2:C$6,0))) -> 0 | W18: =IF(P18="",0,INDEX(Sheet2!A$2:A$6,MATCH(P18,Sheet2!C$2:C$6,0))) -> 0 | X18: =IF(Q18="",0,INDEX(Sheet2!A$2:A$6,MATCH(Q18,Sheet2!C$2:C$6,0))) -> 0 | Y18: =IF(R18="",0,INDEX(Sheet2!A$2:A$6,MATCH(R18,Sheet2!C$2:C$6,0))) -> 0 | Z18: =IF(S18="Yes",I18-SUM(T18:Y18),0) -> 0 | AA18: =IF(I18>=7500,"E",IF(I18>=6800,"D",IF(I18>=4200,"C",IF(I18>=3000,"B",IF(I18>=750,"A","Below Slab"))))) -> E | AB18: =IF(I18>=7500,"Samsung front-load washing machine",IF(I18>=6800,"Apple iPad",IF(I18>=4200,"Robot Vacuum cleaner",IF(I18>=3000,"Sony - sound bar, woofer and speakers",IF(I18>=750,"Foot massager","Not eligible"))))) -> Samsung front-load washing machine
A19: 001fw00000CimN0AAJ | B19: QUALITY SALES CORPORATION | C19: R. K. ENTERPRISES | D19: MADHYA PRADESH | E19: INDORE | F19: No | G19: Central | H19: 41.71 | I19: 1042.75 | J19: =IF(SUM(T19:Z19)=0,"",SUM(T19:Z19)) | K19: =IF(J19="","",I19-J19) | L19: Foot massager | T19: =IF(M19="",0,INDEX(Sheet2!A$2:A$6,MATCH(M19,Sheet2!C$2:C$6,0))) -> 0 | U19: =IF(N19="",0,INDEX(Sheet2!A$2:A$6,MATCH(N19,Sheet2!C$2:C$6,0))) -> 0 | V19: =IF(O19="",0,INDEX(Sheet2!A$2:A$6,MATCH(O19,Sheet2!C$2:C$6,0))) -> 0 | W19: =IF(P19="",0,INDEX(Sheet2!A$2:A$6,MATCH(P19,Sheet2!C$2:C$6,0))) -> 0 | X19: =IF(Q19="",0,INDEX(Sheet2!A$2:A$6,MATCH(Q19,Sheet2!C$2:C$6,0))) -> 0 | Y19: =IF(R19="",0,INDEX(Sheet2!A$2:A$6,MATCH(R19,Sheet2!C$2:C$6,0))) -> 0 | Z19: =IF(S19="Yes",I19-SUM(T19:Y19),0) -> 0 | AA19: =IF(I19>=7500,"E",IF(I19>=6800,"D",IF(I19>=4200,"C",IF(I19>=3000,"B",IF(I19>=750,"A","Below Slab"))))) -> A | AB19: =IF(I19>=7500,"Samsung front-load washing machine",IF(I19>=6800,"Apple iPad",IF(I19>=4200,"Robot Vacuum cleaner",IF(I19>=3000,"Sony - sound bar, woofer and speakers",IF(I19>=750,"Foot massager","Not eligible"))))) -> Foot massager
A20: 001J1000005ZUB5IAO | B20: Vijay Mohan Steel Industries PVT. LTD. | C20: R. K. ENTERPRISES | D20: MADHYA PRADESH | E20: INDORE | F20: No | G20: Central | H20: 447.8 | I20: 16792.5 | J20: =IF(SUM(T20:Z20)=0,"",SUM(T20:Z20)) | K20: =IF(J20="","",I20-J20) | L20: Samsung front-load washing machine | T20: =IF(M20="",0,INDEX(Sheet2!A$2:A$6,MATCH(M20,Sheet2!C$2:C$6,0))) -> 0 | U20: =IF(N20="",0,INDEX(Sheet2!A$2:A$6,MATCH(N20,Sheet2!C$2:C$6,0))) -> 0 | V20: =IF(O20="",0,INDEX(Sheet2!A$2:A$6,MATCH(O20,Sheet2!C$2:C$6,0))) -> 0 | W20: =IF(P20="",0,INDEX(Sheet2!A$2:A$6,MATCH(P20,Sheet2!C$2:C$6,0))) -> 0 | X20: =IF(Q20="",0,INDEX(Sheet2!A$2:A$6,MATCH(Q20,Sheet2!C$2:C$6,0))) -> 0 | Y20: =IF(R20="",0,INDEX(Sheet2!A$2:A$6,MATCH(R20,Sheet2!C$2:C$6,0))) -> 0 | Z20: =IF(S20="Yes",I20-SUM(T20:Y20),0) -> 0 | AA20: =IF(I20>=7500,"E",IF(I20>=6800,"D",IF(I20>=4200,"C",IF(I20>=3000,"B",IF(I20>=750,"A","Below Slab"))))) -> E | AB20: =IF(I20>=7500,"Samsung front-load washing machine",IF(I20>=6800,"Apple iPad",IF(I20>=4200,"Robot Vacuum cleaner",IF(I20>=3000,"Sony - sound bar, woofer and speakers",IF(I20>=750,"Foot massager","Not eligible"))))) -> Samsung front-load washing machine
A21: 001J100000RzabCIAR | B21: MAHAVEER TRADERS | C21: R. K. ENTERPRISES | D21: MADHYA PRADESH | E21: JHABUA | F21: No | G21: Central | H21: 82.93 | I21: 2280.575 | J21: =IF(SUM(T21:Z21)=0,"",SUM(T21:Z21)) | K21: =IF(J21="","",I21-J21) | L21: Foot massager | T21: =IF(M21="",0,INDEX(Sheet2!A$2:A$6,MATCH(M21,Sheet2!C$2:C$6,0))) -> 0 | U21: =IF(N21="",0,INDEX(Sheet2!A$2:A$6,MATCH(N21,Sheet2!C$2:C$6,0))) -> 0 | V21: =IF(O21="",0,INDEX(Sheet2!A$2:A$6,MATCH(O21,Sheet2!C$2:C$6,0))) -> 0 | W21: =IF(P21="",0,INDEX(Sheet2!A$2:A$6,MATCH(P21,Sheet2!C$2:C$6,0))) -> 0 | X21: =IF(Q21="",0,INDEX(Sheet2!A$2:A$6,MATCH(Q21,Sheet2!C$2:C$6,0))) -> 0 | Y21: =IF(R21="",0,INDEX(Sheet2!A$2:A$6,MATCH(R21,Sheet2!C$2:C$6,0))) -> 0 | Z21: =IF(S21="Yes",I21-SUM(T21:Y21),0) -> 0 | AA21: =IF(I21>=7500,"E",IF(I21>=6800,"D",IF(I21>=4200,"C",IF(I21>=3000,"B",IF(I21>=750,"A","Below Slab"))))) -> A | AB21: =IF(I21>=7500,"Samsung front-load washing machine",IF(I21>=6800,"Apple iPad",IF(I21>=4200,"Robot Vacuum cleaner",IF(I21>=3000,"Sony - sound bar, woofer and speakers",IF(I21>=750,"Foot massager","Not eligible"))))) -> Foot massager
A22: 0015g00001LVcLpAAL | B22: NITA STEEL SUPPLIERS | C22: R. K. ENTERPRISES | D22: MADHYA PRADESH | E22: INDORE | F22: No | G22: Central | H22: 432.32 | I22: 16212 | J22: =IF(SUM(T22:Z22)=0,"",SUM(T22:Z22)) | K22: =IF(J22="","",I22-J22) | L22: Samsung front-load washing machine | T22: =IF(M22="",0,INDEX(Sheet2!A$2:A$6,MATCH(M22,Sheet2!C$2:C$6,0))) -> 0 | U22: =IF(N22="",0,INDEX(Sheet2!A$2:A$6,MATCH(N22,Sheet2!C$2:C$6,0))) -> 0 | V22: =IF(O22="",0,INDEX(Sheet2!A$2:A$6,MATCH(O22,Sheet2!C$2:C$6,0))) -> 0 | W22: =IF(P22="",0,INDEX(Sheet2!A$2:A$6,MATCH(P22,Sheet2!C$2:C$6,0))) -> 0 | X22: =IF(Q22="",0,INDEX(Sheet2!A$2:A$6,MATCH(Q22,Sheet2!C$2:C$6,0))) -> 0 | Y22: =IF(R22="",0,INDEX(Sheet2!A$2:A$6,MATCH(R22,Sheet2!C$2:C$6,0))) -> 0 | Z22: =IF(S22="Yes",I22-SUM(T22:Y22),0) -> 0 | AA22: =IF(I22>=7500,"E",IF(I22>=6800,"D",IF(I22>=4200,"C",IF(I22>=3000,"B",IF(I22>=750,"A","Below Slab"))))) -> E | AB22: =IF(I22>=7500,"Samsung front-load washing machine",IF(I22>=6800,"Apple iPad",IF(I22>=4200,"Robot Vacuum cleaner",IF(I22>=3000,"Sony - sound bar, woofer and speakers",IF(I22>=750,"Foot massager","Not eligible"))))) -> Samsung front-load washing machine
... A44: 001J100000F4YxqIAF | B44: KALING HARDWARE AND CONSTRUCTION | C44: SACHDEVA ISPAT PRIVATE LIMITED | D44: ODISHA | E44: KENDUJHAR | F44: No | G44: Central | H44: 70.2 | I44: 1930.5 | J44: =IF(SUM(T44:Z44)=0,"",SUM(T44:Z44)) | K44: =IF(J44="","",I44-J44) | L44: Foot massager | T44: =IF(M44="",0,INDEX(Sheet2!A$2:A$6,MATCH(M44,Sheet2!C$2:C$6,0))) -> 0 | U44: =IF(N44="",0,INDEX(Sheet2!A$2:A$6,MATCH(N44,Sheet2!C$2:C$6,0))) -> 0 | V44: =IF(O44="",0,INDEX(Sheet2!A$2:A$6,MATCH(O44,Sheet2!C$2:C$6,0))) -> 0 | W44: =IF(P44="",0,INDEX(Sheet2!A$2:A$6,MATCH(P44,Sheet2!C$2:C$6,0))) -> 0 | X44: =IF(Q44="",0,INDEX(Sheet2!A$2:A$6,MATCH(Q44,Sheet2!C$2:C$6,0))) -> 0 | Y44: =IF(R44="",0,INDEX(Sheet2!A$2:A$6,MATCH(R44,Sheet2!C$2:C$6,0))) -> 0 | Z44: =IF(S44="Yes",I44-SUM(T44:Y44),0) -> 0 | AA44: =IF(I44>=7500,"E",IF(I44>=6800,"D",IF(I44>=4200,"C",IF(I44>=3000,"B",IF(I44>=750,"A","Below Slab"))))) -> A | AB44: =IF(I44>=7500,"Samsung front-load washing machine",IF(I44>=6800,"Apple iPad",IF(I44>=4200,"Robot Vacuum cleaner",IF(I44>=3000,"Sony - sound bar, woofer and speakers",IF(I44>=750,"Foot massager","Not eligible"))))) -> Foot massager
A45: 001J100000VlcQxIAJ | B45: MAA VAISHNAVI TRADERS | C45: KHARAKIA METALS PRIVATE LIMITED | D45: 0 | E45: 0 | F45: No | G45: East | H45: 50 | I45: 1375 | J45: =IF(SUM(T45:Z45)=0,"",SUM(T45:Z45)) | K45: =IF(J45="","",I45-J45) | L45: Foot massager | T45: =IF(M45="",0,INDEX(Sheet2!A$2:A$6,MATCH(M45,Sheet2!C$2:C$6,0))) -> 0 | U45: =IF(N45="",0,INDEX(Sheet2!A$2:A$6,MATCH(N45,Sheet2!C$2:C$6,0))) -> 0 | V45: =IF(O45="",0,INDEX(Sheet2!A$2:A$6,MATCH(O45,Sheet2!C$2:C$6,0))) -> 0 | W45: =IF(P45="",0,INDEX(Sheet2!A$2:A$6,MATCH(P45,Sheet2!C$2:C$6,0))) -> 0 | X45: =IF(Q45="",0,INDEX(Sheet2!A$2:A$6,MATCH(Q45,Sheet2!C$2:C$6,0))) -> 0 | Y45: =IF(R45="",0,INDEX(Sheet2!A$2:A$6,MATCH(R45,Sheet2!C$2:C$6,0))) -> 0 | Z45: =IF(S45="Yes",I45-SUM(T45:Y45),0) -> 0 | AA45: =IF(I45>=7500,"E",IF(I45>=6800,"D",IF(I45>=4200,"C",IF(I45>=3000,"B",IF(I45>=750,"A","Below Slab"))))) -> A | AB45: =IF(I45>=7500,"Samsung front-load washing machine",IF(I45>=6800,"Apple iPad",IF(I45>=4200,"Robot Vacuum cleaner",IF(I45>=3000,"Sony - sound bar, woofer and speakers",IF(I45>=750,"Foot massager","Not eligible"))))) -> Foot massager
A46: 001fw00000KuTtSAAV | B46: M. A. TRADERS | C46: KHARAKIA METALS PRIVATE LIMITED | D46: BIHAR | E46: DARBHANGA | F46: No | G46: East | H46: 36.9 | I46: 922.5 | J46: =IF(SUM(T46:Z46)=0,"",SUM(T46:Z46)) | K46: =IF(J46="","",I46-J46) | L46: Foot massager | T46: =IF(M46="",0,INDEX(Sheet2!A$2:A$6,MATCH(M46,Sheet2!C$2:C$6,0))) -> 0 | U46: =IF(N46="",0,INDEX(Sheet2!A$2:A$6,MATCH(N46,Sheet2!C$2:C$6,0))) -> 0 | V46: =IF(O46="",0,INDEX(Sheet2!A$2:A$6,MATCH(O46,Sheet2!C$2:C$6,0))) -> 0 | W46: =IF(P46="",0,INDEX(Sheet2!A$2:A$6,MATCH(P46,Sheet2!C$2:C$6,0))) -> 0 | X46: =IF(Q46="",0,INDEX(Sheet2!A$2:A$6,MATCH(Q46,Sheet2!C$2:C$6,0))) -> 0 | Y46: =IF(R46="",0,INDEX(Sheet2!A$2:A$6,MATCH(R46,Sheet2!C$2:C$6,0))) -> 0 | Z46: =IF(S46="Yes",I46-SUM(T46:Y46),0) -> 0 | AA46: =IF(I46>=7500,"E",IF(I46>=6800,"D",IF(I46>=4200,"C",IF(I46>=3000,"B",IF(I46>=750,"A","Below Slab"))))) -> A | AB46: =IF(I46>=7500,"Samsung front-load washing machine",IF(I46>=6800,"Apple iPad",IF(I46>=4200,"Robot Vacuum cleaner",IF(I46>=3000,"Sony - sound bar, woofer and speakers",IF(I46>=750,"Foot massager","Not eligible"))))) -> Foot massager
A47: 001fw00000Kvt16AAB | B47: SHREE VISHNU STEEL | C47: KHARAKIA METALS PRIVATE LIMITED | D47: BIHAR | E47: GAYA | F47: No | G47: East | H47: 41.84 | I47: 1046 | J47: =IF(SUM(T47:Z47)=0,"",SUM(T47:Z47)) | K47: =IF(J47="","",I47-J47) | L47: Foot massager | T47: =IF(M47="",0,INDEX(Sheet2!A$2:A$6,MATCH(M47,Sheet2!C$2:C$6,0))) -> 0 | U47: =IF(N47="",0,INDEX(Sheet2!A$2:A$6,MATCH(N47,Sheet2!C$2:C$6,0))) -> 0 | V47: =IF(O47="",0,INDEX(Sheet2!A$2:A$6,MATCH(O47,Sheet2!C$2:C$6,0))) -> 0 | W47: =IF(P47="",0,INDEX(Sheet2!A$2:A$6,MATCH(P47,Sheet2!C$2:C$6,0))) -> 0 | X47: =IF(Q47="",0,INDEX(Sheet2!A$2:A$6,MATCH(Q47,Sheet2!C$2:C$6,0))) -> 0 | Y47: =IF(R47="",0,INDEX(Sheet2!A$2:A$6,MATCH(R47,Sheet2!C$2:C$6,0))) -> 0 | Z47: =IF(S47="Yes",I47-SUM(T47:Y47),0) -> 0 | AA47: =IF(I47>=7500,"E",IF(I47>=6800,"D",IF(I47>=4200,"C",IF(I47>=3000,"B",IF(I47>=750,"A","Below Slab"))))) -> A | AB47: =IF(I47>=7500,"Samsung front-load washing machine",IF(I47>=6800,"Apple iPad",IF(I47>=4200,"Robot Vacuum cleaner",IF(I47>=3000,"Sony - sound bar, woofer and speakers",IF(I47>=750,"Foot massager","Not eligible"))))) -> Foot massager
A48: 001fw00000HJ5NBAA1 | B48: M/S MAA KALIKA HARDWARE | C48: KHARAKIA METALS PRIVATE LIMITED | D48: BIHAR | E48: MADHUBANI | F48: No | G48: East | H48: 32.3 | I48: 807.5 | J48: =IF(SUM(T48:Z48)=0,"",SUM(T48:Z48)) | K48: =IF(J48="","",I48-J48) | L48: Foot massager | T48: =IF(M48="",0,INDEX(Sheet2!A$2:A$6,MATCH(M48,Sheet2!C$2:C$6,0))) -> 0 | U48: =IF(N48="",0,INDEX(Sheet2!A$2:A$6,MATCH(N48,Sheet2!C$2:C$6,0))) -> 0 | V48: =IF(O48="",0,INDEX(Sheet2!A$2:A$6,MATCH(O48,Sheet2!C$2:C$6,0))) -> 0 | W48: =IF(P48="",0,INDEX(Sheet2!A$2:A$6,MATCH(P48,Sheet2!C$2:C$6,0))) -> 0 | X48: =IF(Q48="",0,INDEX(Sheet2!A$2:A$6,MATCH(Q48,Sheet2!C$2:C$6,0))) -> 0 | Y48: =IF(R48="",0,INDEX(Sheet2!A$2:A$6,MATCH(R48,Sheet2!C$2:C$6,0))) -> 0 | Z48: =IF(S48="Yes",I48-SUM(T48:Y48),0) -> 0 | AA48: =IF(I48>=7500,"E",IF(I48>=6800,"D",IF(I48>=4200,"C",IF(I48>=3000,"B",IF(I48>=750,"A","Below Slab"))))) -> A | AB48: =IF(I48>=7500,"Samsung front-load washing machine",IF(I48>=6800,"Apple iPad",IF(I48>=4200,"Robot Vacuum cleaner",IF(I48>=3000,"Sony - sound bar, woofer and speakers",IF(I48>=750,"Foot massager","Not eligible"))))) -> Foot massager
A49: 001J100000VnWk6IAF | B49: DIDWANIA STEELS LLP | C49: KHARAKIA METALS PRIVATE LIMITED | D49: BIHAR | E49: BHAGALPUR | F49: No | G49: East | H49: 67 | I49: 1842.5 | J49: =IF(SUM(T49:Z49)=0,"",SUM(T49:Z49)) | K49: =IF(J49="","",I49-J49) | L49: Foot massager | T49: =IF(M49="",0,INDEX(Sheet2!A$2:A$6,MATCH(M49,Sheet2!C$2:C$6,0))) -> 0 | U49: =IF(N49="",0,INDEX(Sheet2!A$2:A$6,MATCH(N49,Sheet2!C$2:C$6,0))) -> 0 | V49: =IF(O49="",0,INDEX(Sheet2!A$2:A$6,MATCH(O49,Sheet2!C$2:C$6,0))) -> 0 | W49: =IF(P49="",0,INDEX(Sheet2!A$2:A$6,MATCH(P49,Sheet2!C$2:C$6,0))) -> 0 | X49: =IF(Q49="",0,INDEX(Sheet2!A$2:A$6,MATCH(Q49,Sheet2!C$2:C$6,0))) -> 0 | Y49: =IF(R49="",0,INDEX(Sheet2!A$2:A$6,MATCH(R49,Sheet2!C$2:C$6,0))) -> 0 | Z49: =IF(S49="Yes",I49-SUM(T49:Y49),0) -> 0 | AA49: =IF(I49>=7500,"E",IF(I49>=6800,"D",IF(I49>=4200,"C",IF(I49>=3000,"B",IF(I49>=750,"A","Below Slab"))))) -> A | AB49: =IF(I49>=7500,"Samsung front-load washing machine",IF(I49>=6800,"Apple iPad",IF(I49>=4200,"Robot Vacuum cleaner",IF(I49>=3000,"Sony - sound bar, woofer and speakers",IF(I49>=750,"Foot massager","Not eligible"))))) -> Foot massager
A50: 001J100000Vm6rJIAR | B50: BESIM INDUSTRIES PRIVATE LIMITED | C50: KHARAKIA METALS PRIVATE LIMITED | D50: BIHAR | E50: ROHTAS | F50: No | G50: East | H50: 36 | I50: 900 | J50: =IF(SUM(T50:Z50)=0,"",SUM(T50:Z50)) | K50: =IF(J50="","",I50-J50) | L50: Foot massager | T50: =IF(M50="",0,INDEX(Sheet2!A$2:A$6,MATCH(M50,Sheet2!C$2:C$6,0))) -> 0 | U50: =IF(N50="",0,INDEX(Sheet2!A$2:A$6,MATCH(N50,Sheet2!C$2:C$6,0))) -> 0 | V50: =IF(O50="",0,INDEX(Sheet2!A$2:A$6,MATCH(O50,Sheet2!C$2:C$6,0))) -> 0 | W50: =IF(P50="",0,INDEX(Sheet2!A$2:A$6,MATCH(P50,Sheet2!C$2:C$6,0))) -> 0 | X50: =IF(Q50="",0,INDEX(Sheet2!A$2:A$6,MATCH(Q50,Sheet2!C$2:C$6,0))) -> 0 | Y50: =IF(R50="",0,INDEX(Sheet2!A$2:A$6,MATCH(R50,Sheet2!C$2:C$6,0))) -> 0 | Z50: =IF(S50="Yes",I50-SUM(T50:Y50),0) -> 0 | AA50: =IF(I50>=7500,"E",IF(I50>=6800,"D",IF(I50>=4200,"C",IF(I50>=3000,"B",IF(I50>=750,"A","Below Slab"))))) -> A | AB50: =IF(I50>=7500,"Samsung front-load washing machine",IF(I50>=6800,"Apple iPad",IF(I50>=4200,"Robot Vacuum cleaner",IF(I50>=3000,"Sony - sound bar, woofer and speakers",IF(I50>=750,"Foot massager","Not eligible"))))) -> Foot massager
A51: 001J1000006TDs4IAG | B51: ZAFAR TRADING COMPANY | C51: KHARAKIA METALS PRIVATE LIMITED | D51: BIHAR | E51: GAYA | F51: No | G51: East | H51: 42 | I51: 1050 | J51: =IF(SUM(T51:Z51)=0,"",SUM(T51:Z51)) | K51: =IF(J51="","",I51-J51) | L51: Foot massager | T51: =IF(M51="",0,INDEX(Sheet2!A$2:A$6,MATCH(M51,Sheet2!C$2:C$6,0))) -> 0 | U51: =IF(N51="",0,INDEX(Sheet2!A$2:A$6,MATCH(N51,Sheet2!C$2:C$6,0))) -> 0 | V51: =IF(O51="",0,INDEX(Sheet2!A$2:A$6,MATCH(O51,Sheet2!C$2:C$6,0))) -> 0 | W51: =IF(P51="",0,INDEX(Sheet2!A$2:A$6,MATCH(P51,Sheet2!C$2:C$6,0))) -> 0 | X51: =IF(Q51="",0,INDEX(Sheet2!A$2:A$6,MATCH(Q51,Sheet2!C$2:C$6,0))) -> 0 | Y51: =IF(R51="",0,INDEX(Sheet2!A$2:A$6,MATCH(R51,Sheet2!C$2:C$6,0))) -> 0 | Z51: =IF(S51="Yes",I51-SUM(T51:Y51),0) -> 0 | AA51: =IF(I51>=7500,"E",IF(I51>=6800,"D",IF(I51>=4200,"C",IF(I51>=3000,"B",IF(I51>=750,"A","Below Slab"))))) -> A | AB51: =IF(I51>=7500,"Samsung front-load washing machine",IF(I51>=6800,"Apple iPad",IF(I51>=4200,"Robot Vacuum cleaner",IF(I51>=3000,"Sony - sound bar, woofer and speakers",IF(I51>=750,"Foot massager","Not eligible"))))) -> Foot massager
A52: 001fw00000Gb5PKAAZ | B52: Lead - 7903576323 | C52: SUBH NEXTGEN PRIVATE LIMITED | D52: BIHAR | E52: SIWAN | F52: No | G52: East | H52: 31.08 | I52: 777 | J52: =IF(SUM(T52:Z52)=0,"",SUM(T52:Z52)) | K52: =IF(J52="","",I52-J52) | L52: Foot massager | T52: =IF(M52="",0,INDEX(Sheet2!A$2:A$6,MATCH(M52,Sheet2!C$2:C$6,0))) -> 0 | U52: =IF(N52="",0,INDEX(Sheet2!A$2:A$6,MATCH(N52,Sheet2!C$2:C$6,0))) -> 0 | V52: =IF(O52="",0,INDEX(Sheet2!A$2:A$6,MATCH(O52,Sheet2!C$2:C$6,0))) -> 0 | W52: =IF(P52="",0,INDEX(Sheet2!A$2:A$6,MATCH(P52,Sheet2!C$2:C$6,0))) -> 0 | X52: =IF(Q52="",0,INDEX(Sheet2!A$2:A$6,MATCH(Q52,Sheet2!C$2:C$6,0))) -> 0 | Y52: =IF(R52="",0,INDEX(Sheet2!A$2:A$6,MATCH(R52,Sheet2!C$2:C$6,0))) -> 0 | Z52: =IF(S52="Yes",I52-SUM(T52:Y52),0) -> 0 | AA52: =IF(I52>=7500,"E",IF(I52>=6800,"D",IF(I52>=4200,"C",IF(I52>=3000,"B",IF(I52>=750,"A","Below Slab"))))) -> A | AB52: =IF(I52>=7500,"Samsung front-load washing machine",IF(I52>=6800,"Apple iPad",IF(I52>=4200,"Robot Vacuum cleaner",IF(I52>=3000,"Sony - sound bar, woofer and speakers",IF(I52>=750,"Foot massager","Not eligible"))))) -> Foot massager
A53: 001fw00000EdKhyAAF | B53: M/S KAMAL INFRA | C53: M/S REAL DREAMS ENTERPRISES | D53: JHARKHAND | E53: RANCHI | F53: No | G53: East | H53: 31.61 | I53: 790.25 | J53: =IF(SUM(T53:Z53)=0,"",SUM(T53:Z53)) | K53: =IF(J53="","",I53-J53) | L53: Foot massager | T53: =IF(M53="",0,INDEX(Sheet2!A$2:A$6,MATCH(M53,Sheet2!C$2:C$6,0))) -> 0 | U53: =IF(N53="",0,INDEX(Sheet2!A$2:A$6,MATCH(N53,Sheet2!C$2:C$6,0))) -> 0 | V53: =IF(O53="",0,INDEX(Sheet2!A$2:A$6,MATCH(O53,Sheet2!C$2:C$6,0))) -> 0 | W53: =IF(P53="",0,INDEX(Sheet2!A$2:A$6,MATCH(P53,Sheet2!C$2:C$6,0))) -> 0 | X53: =IF(Q53="",0,INDEX(Sheet2!A$2:A$6,MATCH(Q53,Sheet2!C$2:C$6,0))) -> 0 | Y53: =IF(R53="",0,INDEX(Sheet2!A$2:A$6,MATCH(R53,Sheet2!C$2:C$6,0))) -> 0 | Z53: =IF(S53="Yes",I53-SUM(T53:Y53),0) -> 0 | AA53: =IF(I53>=7500,"E",IF(I53>=6800,"D",IF(I53>=4200,"C",IF(I53>=3000,"B",IF(I53>=750,"A","Below Slab"))))) -> A | AB53: =IF(I53>=7500,"Samsung front-load washing machine",IF(I53>=6800,"Apple iPad",IF(I53>=4200,"Robot Vacuum cleaner",IF(I53>=3000,"Sony - sound bar, woofer and speakers",IF(I53>=750,"Foot massager","Not eligible"))))) -> Foot massager
A54: 001fw000003K5OPAA0 | B54: SHREE TRADERS | C54: M/S REAL DREAMS ENTERPRISES | D54: JHARKHAND | E54: RANCHI | F54: No | G54: East | H54: 32.04 | I54: 801 | J54: =IF(SUM(T54:Z54)=0,"",SUM(T54:Z54)) | K54: =IF(J54="","",I54-J54) | L54: Foot massager | T54: =IF(M54="",0,INDEX(Sheet2!A$2:A$6,MATCH(M54,Sheet2!C$2:C$6,0))) -> 0 | U54: =IF(N54="",0,INDEX(Sheet2!A$2:A$6,MATCH(N54,Sheet2!C$2:C$6,0))) -> 0 | V54: =IF(O54="",0,INDEX(Sheet2!A$2:A$6,MATCH(O54,Sheet2!C$2:C$6,0))) -> 0 | W54: =IF(P54="",0,INDEX(Sheet2!A$2:A$6,MATCH(P54,Sheet2!C$2:C$6,0))) -> 0 | X54: =IF(Q54="",0,INDEX(Sheet2!A$2:A$6,MATCH(Q54,Sheet2!C$2:C$6,0))) -> 0 | Y54: =IF(R54="",0,INDEX(Sheet2!A$2:A$6,MATCH(R54,Sheet2!C$2:C$6,0))) -> 0 | Z54: =IF(S54="Yes",I54-SUM(T54:Y54),0) -> 0 | AA54: =IF(I54>=7500,"E",IF(I54>=6800,"D",IF(I54>=4200,"C",IF(I54>=3000,"B",IF(I54>=750,"A","Below Slab"))))) -> A | AB54: =IF(I54>=7500,"Samsung front-load washing machine",IF(I54>=6800,"Apple iPad",IF(I54>=4200,"Robot Vacuum cleaner",IF(I54>=3000,"Sony - sound bar, woofer and speakers",IF(I54>=750,"Foot massager","Not eligible"))))) -> Foot massager
A55: 001fw000007SMKwAAO | B55: G AND SONS | C55: TIRUPATI SALES | D55: JHARKHAND | E55: BOKARO | F55: No | G55: East | H55: 33.06 | I55: 826.5 | J55: =IF(SUM(T55:Z55)=0,"",SUM(T55:Z55)) | K55: =IF(J55="","",I55-J55) | L55: Foot massager | T55: =IF(M55="",0,INDEX(Sheet2!A$2:A$6,MATCH(M55,Sheet2!C$2:C$6,0))) -> 0 | U55: =IF(N55="",0,INDEX(Sheet2!A$2:A$6,MATCH(N55,Sheet2!C$2:C$6,0))) -> 0 | V55: =IF(O55="",0,INDEX(Sheet2!A$2:A$6,MATCH(O55,Sheet2!C$2:C$6,0))) -> 0 | W55: =IF(P55="",0,INDEX(Sheet2!A$2:A$6,MATCH(P55,Sheet2!C$2:C$6,0))) -> 0 | X55: =IF(Q55="",0,INDEX(Sheet2!A$2:A$6,MATCH(Q55,Sheet2!C$2:C$6,0))) -> 0 | Y55: =IF(R55="",0,INDEX(Sheet2!A$2:A$6,MATCH(R55,Sheet2!C$2:C$6,0))) -> 0 | Z55: =IF(S55="Yes",I55-SUM(T55:Y55),0) -> 0 | AA55: =IF(I55>=7500,"E",IF(I55>=6800,"D",IF(I55>=4200,"C",IF(I55>=3000,"B",IF(I55>=750,"A","Below Slab"))))) -> A | AB55: =IF(I55>=7500,"Samsung front-load washing machine",IF(I55>=6800,"Apple iPad",IF(I55>=4200,"Robot Vacuum cleaner",IF(I55>=3000,"Sony - sound bar, woofer and speakers",IF(I55>=750,"Foot massager","Not eligible"))))) -> Foot massager
A56: 001fw000005GxVwAAK | B56: MONDAL ENTERPRISE | C56: CHANDRA TRADERS | D56: WEST BENGAL | E56: MURSHIDABAD | F56: No | G56: East | H56: 35 | I56: 875 | J56: =IF(SUM(T56:Z56)=0,"",SUM(T56:Z56)) | K56: =IF(J56="","",I56-J56) | L56: Foot massager | T56: =IF(M56="",0,INDEX(Sheet2!A$2:A$6,MATCH(M56,Sheet2!C$2:C$6,0))) -> 0 | U56: =IF(N56="",0,INDEX(Sheet2!A$2:A$6,MATCH(N56,Sheet2!C$2:C$6,0))) -> 0 | V56: =IF(O56="",0,INDEX(Sheet2!A$2:A$6,MATCH(O56,Sheet2!C$2:C$6,0))) -> 0 | W56: =IF(P56="",0,INDEX(Sheet2!A$2:A$6,MATCH(P56,Sheet2!C$2:C$6,0))) -> 0 | X56: =IF(Q56="",0,INDEX(Sheet2!A$2:A$6,MATCH(Q56,Sheet2!C$2:C$6,0))) -> 0 | Y56: =IF(R56="",0,INDEX(Sheet2!A$2:A$6,MATCH(R56,Sheet2!C$2:C$6,0))) -> 0 | Z56: =IF(S56="Yes",I56-SUM(T56:Y56),0) -> 0 | AA56: =IF(I56>=7500,"E",IF(I56>=6800,"D",IF(I56>=4200,"C",IF(I56>=3000,"B",IF(I56>=750,"A","Below Slab"))))) -> A | AB56: =IF(I56>=7500,"Samsung front-load washing machine",IF(I56>=6800,"Apple iPad",IF(I56>=4200,"Robot Vacuum cleaner",IF(I56>=3000,"Sony - sound bar, woofer and speakers",IF(I56>=750,"Foot massager","Not eligible"))))) -> Foot massager
A57: 001J100000Vl8ygIAB | B57: NIRMALA HARDWARE | C57: KEDIA PIPES PRIVATE LMITED | D57: WEST BENGAL | E57: 24 PARAGANAS SOUTH | F57: No | G57: East | H57: 57.94 | I57: 1593.35 | J57: =IF(SUM(T57:Z57)=0,"",SUM(T57:Z57)) | K57: =IF(J57="","",I57-J57) | L57: Foot massager | T57: =IF(M57="",0,INDEX(Sheet2!A$2:A$6,MATCH(M57,Sheet2!C$2:C$6,0))) -> 0 | U57: =IF(N57="",0,INDEX(Sheet2!A$2:A$6,MATCH(N57,Sheet2!C$2:C$6,0))) -> 0 | V57: =IF(O57="",0,INDEX(Sheet2!A$2:A$6,MATCH(O57,Sheet2!C$2:C$6,0))) -> 0 | W57: =IF(P57="",0,INDEX(Sheet2!A$2:A$6,MATCH(P57,Sheet2!C$2:C$6,0))) -> 0 | X57: =IF(Q57="",0,INDEX(Sheet2!A$2:A$6,MATCH(Q57,Sheet2!C$2:C$6,0))) -> 0 | Y57: =IF(R57="",0,INDEX(Sheet2!A$2:A$6,MATCH(R57,Sheet2!C$2:C$6,0))) -> 0 | Z57: =IF(S57="Yes",I57-SUM(T57:Y57),0) -> 0 | AA57: =IF(I57>=7500,"E",IF(I57>=6800,"D",IF(I57>=4200,"C",IF(I57>=3000,"B",IF(I57>=750,"A","Below Slab"))))) -> A | AB57: =IF(I57>=7500,"Samsung front-load washing machine",IF(I57>=6800,"Apple iPad",IF(I57>=4200,"Robot Vacuum cleaner",IF(I57>=3000,"Sony - sound bar, woofer and speakers",IF(I57>=750,"Foot massager","Not eligible"))))) -> Foot massager
... A61: 001fw00000Axf1OAAR | B61: BUILDERS ENTERPRISE | C61: SILIGURI BUILDERS STORES | D61: WEST BENGAL | E61: KALIMPONG | F61: No | G61: East | H61: 188.27 | I61: 6118.775 | J61: =IF(SUM(T61:Z61)=0,"",SUM(T61:Z61)) | K61: =IF(J61="","",I61-J61) | L61: Robot Vacuum cleaner | T61: =IF(M61="",0,INDEX(Sheet2!A$2:A$6,MATCH(M61,Sheet2!C$2:C$6,0))) -> 0 | U61: =IF(N61="",0,INDEX(Sheet2!A$2:A$6,MATCH(N61,Sheet2!C$2:C$6,0))) -> 0 | V61: =IF(O61="",0,INDEX(Sheet2!A$2:A$6,MATCH(O61,Sheet2!C$2:C$6,0))) -> 0 | W61: =IF(P61="",0,INDEX(Sheet2!A$2:A$6,MATCH(P61,Sheet2!C$2:C$6,0))) -> 0 | X61: =IF(Q61="",0,INDEX(Sheet2!A$2:A$6,MATCH(Q61,Sheet2!C$2:C$6,0))) -> 0 | Y61: =IF(R61="",0,INDEX(Sheet2!A$2:A$6,MATCH(R61,Sheet2!C$2:C$6,0))) -> 0 | Z61: =IF(S61="Yes",I61-SUM(T61:Y61),0) -> 0 | AA61: =IF(I61>=7500,"E",IF(I61>=6800,"D",IF(I61>=4200,"C",IF(I61>=3000,"B",IF(I61>=750,"A","Below Slab"))))) -> C | AB61: =IF(I61>=7500,"Samsung front-load washing machine",IF(I61>=6800,"Apple iPad",IF(I61>=4200,"Robot Vacuum cleaner",IF(I61>=3000,"Sony - sound bar, woofer and speakers",IF(I61>=750,"Foot massager","Not eligible"))))) -> Robot Vacuum cleaner
A62: 0015g00001V9TjDAAV | B62: Govind Steels | C62: GOBINDGARH IRON LLP | D62: 0 | E62: 0 | F62: No | G62: North | H62: 50 | I62: 1375 | J62: =IF(SUM(T62:Z62)=0,"",SUM(T62:Z62)) | K62: =IF(J62="","",I62-J62) | L62: Foot massager | T62: =IF(M62="",0,INDEX(Sheet2!A$2:A$6,MATCH(M62,Sheet2!C$2:C$6,0))) -> 0 | U62: =IF(N62="",0,INDEX(Sheet2!A$2:A$6,MATCH(N62,Sheet2!C$2:C$6,0))) -> 0 | V62: =IF(O62="",0,INDEX(Sheet2!A$2:A$6,MATCH(O62,Sheet2!C$2:C$6,0))) -> 0 | W62: =IF(P62="",0,INDEX(Sheet2!A$2:A$6,MATCH(P62,Sheet2!C$2:C$6,0))) -> 0 | X62: =IF(Q62="",0,INDEX(Sheet2!A$2:A$6,MATCH(Q62,Sheet2!C$2:C$6,0))) -> 0 | Y62: =IF(R62="",0,INDEX(Sheet2!A$2:A$6,MATCH(R62,Sheet2!C$2:C$6,0))) -> 0 | Z62: =IF(S62="Yes",I62-SUM(T62:Y62),0) -> 0 | AA62: =IF(I62>=7500,"E",IF(I62>=6800,"D",IF(I62>=4200,"C",IF(I62>=3000,"B",IF(I62>=750,"A","Below Slab"))))) -> A | AB62: =IF(I62>=7500,"Samsung front-load washing machine",IF(I62>=6800,"Apple iPad",IF(I62>=4200,"Robot Vacuum cleaner",IF(I62>=3000,"Sony - sound bar, woofer and speakers",IF(I62>=750,"Foot massager","Not eligible"))))) -> Foot massager
A63: 001J100000F4iolIAB | B63: PARBHU DAYAL AND SONS | C63: PAL CEMENT AND STEEL PVT. LTD. | D63: 0 | E63: 0 | F63: No | G63: North | H63: 141.78 | I63: 4253.4 | J63: =IF(SUM(T63:Z63)=0,"",SUM(T63:Z63)) | K63: =IF(J63="","",I63-J63) | L63: Robot Vacuum cleaner | T63: =IF(M63="",0,INDEX(Sheet2!A$2:A$6,MATCH(M63,Sheet2!C$2:C$6,0))) -> 0 | U63: =IF(N63="",0,INDEX(Sheet2!A$2:A$6,MATCH(N63,Sheet2!C$2:C$6,0))) -> 0 | V63: =IF(O63="",0,INDEX(Sheet2!A$2:A$6,MATCH(O63,Sheet2!C$2:C$6,0))) -> 0 | W63: =IF(P63="",0,INDEX(Sheet2!A$2:A$6,MATCH(P63,Sheet2!C$2:C$6,0))) -> 0 | X63: =IF(Q63="",0,INDEX(Sheet2!A$2:A$6,MATCH(Q63,Sheet2!C$2:C$6,0))) -> 0 | Y63: =IF(R63="",0,INDEX(Sheet2!A$2:A$6,MATCH(R63,Sheet2!C$2:C$6,0))) -> 0 | Z63: =IF(S63="Yes",I63-SUM(T63:Y63),0) -> 0 | AA63: =IF(I63>=7500,"E",IF(I63>=6800,"D",IF(I63>=4200,"C",IF(I63>=3000,"B",IF(I63>=750,"A","Below Slab"))))) -> C | AB63: =IF(I63>=7500,"Samsung front-load washing machine",IF(I63>=6800,"Apple iPad",IF(I63>=4200,"Robot Vacuum cleaner",IF(I63>=3000,"Sony - sound bar, woofer and speakers",IF(I63>=750,"Foot massager","Not eligible"))))) -> Robot Vacuum cleaner
A64: 0015g00001dHW5fAAG | B64: M/S DHAN LAXMI TRADERS | C64: SHIVA SALES INDIA CORPORATION | D64: 0 | E64: 0 | F64: No | G64: North | H64: 39 | I64: 975 | J64: =IF(SUM(T64:Z64)=0,"",SUM(T64:Z64)) | K64: =IF(J64="","",I64-J64) | L64: Foot massager | T64: =IF(M64="",0,INDEX(Sheet2!A$2:A$6,MATCH(M64,Sheet2!C$2:C$6,0))) -> 0 | U64: =IF(N64="",0,INDEX(Sheet2!A$2:A$6,MATCH(N64,Sheet2!C$2:C$6,0))) -> 0 | V64: =IF(O64="",0,INDEX(Sheet2!A$2:A$6,MATCH(O64,Sheet2!C$2:C$6,0))) -> 0 | W64: =IF(P64="",0,INDEX(Sheet2!A$2:A$6,MATCH(P64,Sheet2!C$2:C$6,0))) -> 0 | X64: =IF(Q64="",0,INDEX(Sheet2!A$2:A$6,MATCH(Q64,Sheet2!C$2:C$6,0))) -> 0 | Y64: =IF(R64="",0,INDEX(Sheet2!A$2:A$6,MATCH(R64,Sheet2!C$2:C$6,0))) -> 0 | Z64: =IF(S64="Yes",I64-SUM(T64:Y64),0) -> 0 | AA64: =IF(I64>=7500,"E",IF(I64>=6800,"D",IF(I64>=4200,"C",IF(I64>=3000,"B",IF(I64>=750,"A","Below Slab"))))) -> A | AB64: =IF(I64>=7500,"Samsung front-load washing machine",IF(I64>=6800,"Apple iPad",IF(I64>=4200,"Robot Vacuum cleaner",IF(I64>=3000,"Sony - sound bar, woofer and speakers",IF(I64>=750,"Foot massager","Not eligible"))))) -> Foot massager
...

Sheet Sheet2
A1: Points | B1: Gift value (INR) | C1: New Gift | D1: Slab
A2: 750 | B2: =A2*5 -> 3750 | C2: Foot massager | D2: A
A3: 3000 | B3: =A3*5 -> 15000 | C3: Sony - sound bar woofer and speakers | D3: B
A4: 4200 | B4: =A4*5 -> 21000 | C4: Robot Vacuum cleaner | D4: C
A5: 6800 | B5: =A5*5 -> 34000 | C5: Apple iPad | D5: D
A6: 7500 | B6: =A6*5 -> 37500 | C6: Samsung front-load washing machine | D6: E
C7: Amazon Voucher
